Workbook
Name Slicer_Region: #N/A
Name Slicer_Segment: #N/A
Name Slicer_Year: #N/A

Sheet KPI YOY
A3: Row Labels | B3: Sum of Sales | C3: Sum of Profit | D3: Sum of Quantity | E3: Count of Order ID | F3: profit margin
A4: 2011 | B4: 484247.5 | C4: 49543.974 | D4: 7581 | E4: 1993 | F4: 0.10231126
A5: 2012 | B5: 470532.51 | C5: 61618.604 | D5: 7979 | E5: 2102 | F5: 0.13095504
A6: 2013 | B6: 608473.83 | C6: 81726.931 | D6: 9810 | E6: 2580 | F6: 0.13431462
A7: 2014 | B7: 733947.02 | C7: 93507.513 | D7: 12503 | E7: 3319 | F7: 0.12740363
H9: =GETPIVOTDATA("[Measures].[Sum of Sales]",$A$3,"[Table_1].[Year]","[Table_1].[Year].&[2014]")/GETPIVOTDATA("[Measures].[Sum of Sales]",$A$3,"[Table_1].[Year]","[Table_1].[Year].&[2013]")-1 -> 0.20620968 | I9: =GETPIVOTDATA("[Measures].[Sum of Profit]",$A$3,"[Table_1].[Year]","[Table_1].[Year].&[2014]")/GETPIVOTDATA("[Measures].[Sum of Profit]",$A$3,"[Table_1].[Year]","[Table_1].[Year].&[2013]")-1 -> 0.14414566 | J9: =GETPIVOTDATA("[Measures].[Sum of Quantity]",$A$3,"[Table_1].[Year]","[Table_1].[Year].&[2014]")/GETPIVOTDATA("[Measures].[Sum of Quantity]",$A$3,"[Table_1].[Year]","[Table_1].[Year].&[2013]")-1 -> 0.2745158 | K9: =GETPIVOTDATA("[Measures].[Count of Order ID]",$A$3,"[Table_1].[Year]","[Table_1].[Year].&[2014]")/GETPIVOTDATA("[Measures].[Count of Order ID]",$A$3,"[Table_1].[Year]","[Table_1].[Year].&[2013]")-1 -> 0.28643411 | L9: =GETPIVOTDATA("[Measures].[profit margin]",$A$3,"[Table_1].[Year]","[Table_1].[Year].&[2014]")/GETPIVOTDATA("[Measures].[profit margin]",$A$3,"[Table_1].[Year]","[Table_1].[Year].&[2013]")-1 -> -0.051453757

Sheet Data
A1: Row ID | B1: Order ID | C1: Year | D1: Order Date | E1: Ship Date | F1: Ship Mode | G1: Customer ID | H1: Customer Name | I1: Segment | J1: Country | K1: City | L1: State | M1: Postal Code | N1: Region | O1: Product ID | P1: Category | Q1: Sub-Category | R1: Product Name | S1: Sales | T1: Quantity | U1: Discount | V1: Profit | W1: profit_margin
A2: 1 | B2: CA-2013-152156 | C2: =YEAR(Data!$D2) -> 2013 | D2: 41587 | E2: 41590 | F2: Second Class | G2: CG-12520 | H2: Claire Gute | I2: Consumer | J2: United States | K2: Henderson | L2: Kentucky | M2: 42420 | N2: South | O2: FUR-BO-10001798 | P2: Furniture | Q2: Bookcases | R2: Bush Somerset Collection Bookcase | S2: 261.96 | T2: 2 | U2: 0 | V2: 41.9136
A3: 2 | B3: CA-2013-152156 | C3: =YEAR(Data!$D3) -> 2013 | D3: 41587 | E3: 41590 | F3: Second Class | G3: CG-12520 | H3: Claire Gute | I3: Consumer | J3: United States | K3: Henderson | L3: Kentucky | M3: 42420 | N3: South | O3: FUR-CH-10000454 | P3: Furniture | Q3: Chairs | R3: Hon Deluxe Fabric Upholstered Stacking Chairs, Rounded Back | S3: 731.94 | T3: 3 | U3: 0 | V3: 219.582
A4: 3 | B4: CA-2013-138688 | C4: =YEAR(Data!$D4) -> 2013 | D4: 41438 | E4: 41442 | F4: Second Class | G4: DV-13045 | H4: Darrin Van Huff | I4: Corporate | J4: United States | K4: Los Angeles | L4: California | M4: 90036 | N4: West | O4: OFF-LA-10000240 | P4: Office Supplies | Q4: Labels | R4: Self-Adhesive Address Labels for Typewriters by Universal | S4: 14.62 | T4: 2 | U4: 0 | V4: 6.8714 | W4: =Table_1[[#This Row],[Profit]]/Table_1[[#This Row],[Sales]] -> 0.47
A5: 4 | B5: US-2012-108966 | C5: =YEAR(Data!$D5) -> 2012 | D5: 41193 | E5: 41200 | F5: Standard Class | G5: SO-20335 | H5: Sean O'Donnell | I5: Consumer | J5: United States | K5: Fort Lauderdale | L5: Florida | M5: 33311 | N5: South | O5: FUR-TA-10000577 | P5: Furniture | Q5: Tables | R5: Bretford CR4500 Series Slim Rectangular Table | S5: 957.5775 | T5: 5 | U5: 0.45 | V5: -383.031
A6: 5 | B6: US-2012-108966 | C6: =YEAR(Data!$D6) -> 2012 | D6: 41193 | E6: 41200 | F6: Standard Class | G6: SO-20335 | H6: Sean O'Donnell | I6: Consumer | J6: United States | K6: Fort Lauderdale | L6: Florida | M6: 33311 | N6: South | O6: OFF-ST-10000760 | P6: Office Supplies | Q6: Storage | R6: Eldon Fold 'N Roll Cart System | S6: 22.368 | T6: 2 | U6: 0.2 | V6: 2.5164
A7: 6 | B7: CA-2011-115812 | C7: =YEAR(Data!$D7) -> 2011 | D7: 40703 | E7: 40708 | F7: Standard Class | G7: BH-11710 | H7: Brosina Hoffman | I7: Consumer | J7: United States | K7: Los Angeles | L7: California | M7: 90032 | N7: West | O7: FUR-FU-10001487 | P7: Furniture | Q7: Furnishings | R7: Eldon Expressions Wood and Plastic Desk Accessories, Cherry Wood | S7: 48.86 | T7: 7 | U7: 0 | V7: 14.1694 | W7: =Table_1[[#This Row],[Profit]]/Table_1[[#This Row],[Sales]] -> 0.29
A8: 7 | B8: CA-2011-115812 | C8: =YEAR(Data!$D8) -> 2011 | D8: 40703 | E8: 40708 | F8: Standard Class | G8: BH-11710 | H8: Brosina Hoffman | I8: Consumer | J8: United States | K8: Los Angeles | L8: California | M8: 90032 | N8: West | O8: OFF-AR-10002833 | P8: Office Supplies | Q8: Art | R8: Newell 322 | S8: 7.28 | T8: 4 | U8: 0 | V8: 1.9656 | W8: =Table_1[[#This Row],[Profit]]/Table_1[[#This Row],[Sales]] -> 0.27
A9: 8 | B9: CA-2011-115812 | C9: =YEAR(Data!$D9) -> 2011 | D9: 40703 | E9: 40708 | F9: Standard Class | G9: BH-11710 | H9: Brosina Hoffman | I9: Consumer | J9: United States | K9: Los Angeles | L9: California | M9: 90032 | N9: West | O9: TEC-PH-10002275 | P9: Technology | Q9: Phones | R9: Mitel 5320 IP Phone VoIP phone | S9: 907.152 | T9: 6 | U9: 0.2 | V9: 90.7152 | W9: =Table_1[[#This Row],[Profit]]/Table_1[[#This Row],[Sales]] -> 0.1
A10: 9 | B10: CA-2011-115812 | C10: =YEAR(Data!$D10) -> 2011 | D10: 40703 | E10: 40708 | F10: Standard Class | G10: BH-11710 | H10: Brosina Hoffman | I10: Consumer | J10: United States | K10: Los Angeles | L10: California | M10: 90032 | N10: West | O10: OFF-BI-10003910 | P10: Office Supplies | Q10: Binders | R10: DXL Angle-View Binders with Locking Rings by Samsill | S10: 18.504 | T10: 3 | U10: 0.2 | V10: 5.7825 | W10: =Table_1[[#This Row],[Profit]]/Table_1[[#This Row],[Sales]] -> 0.3125
A11: 10 | B11: CA-2011-115812 | C11: =YEAR(Data!$D11) -> 2011 | D11: 40703 | E11: 40708 | F11: Standard Class | G11: BH-11710 | H11: Brosina Hoffman | I11: Consumer | J11: United States | K11: Los Angeles | L11: California | M11: 90032 | N11: West | O11: OFF-AP-10002892 | P11: Office Supplies | Q11: Appliances | R11: Belkin F5C206VTEL 6 Outlet Surge | S11: 114.9 | T11: 5 | U11: 0 | V11: 34.47 | W11: =Table_1[[#This Row],[Profit]]/Table_1[[#This Row],[Sales]] -> 0.3
A12: 11 | B12: CA-2011-115812 | C12: =YEAR(Data!$D12) -> 2011 | D12: 40703 | E12: 40708 | F12: Standard Class | G12: BH-11710 | H12: Brosina Hoffman | I12: Consumer | J12: United States | K12: Los Angeles | L12: California | M12: 90032 | N12: West | O12: FUR-TA-10001539 | P12: Furniture | Q12: Tables | R12: Chromcraft Rectangular Conference Tables | S12: 1706.184 | T12: 9 | U12: 0.2 | V12: 85.3092 | W12: =Table_1[[#This Row],[Profit]]/Table_1[[#This Row],[Sales]] -> 0.05
A13: 12 | B13: CA-2011-115812 | C13: =YEAR(Data!$D13) -> 2011 | D13: 40703 | E13: 40708 | F13: Standard Class | G13: BH-11710 | H13: Brosina Hoffman | I13: Consumer | J13: United States | K13: Los Angeles | L13: California | M13: 90032 | N13: West | O13: TEC-PH-10002033 | P13: Technology | Q13: Phones | R13: Konftel 250 Conference phone - Charcoal black | S13: 911.424 | T13: 4 | U13: 0.2 | V13: 68.3568 | W13: =Table_1[[#This Row],[Profit]]/Table_1[[#This Row],[Sales]] -> 0.075
A14: 13 | B14: CA-2014-114412 | C14: =YEAR(Data!$D14) -> 2014 | D14: 41745 | E14: 41750 | F14: Standard Class | G14: AA-10480 | H14: Andrew Allen | I14: Consumer | J14: United States | K14: Concord | L14: North Carolina | M14: 28027 | N14: South | O14: OFF-PA-10002365 | P14: Office Supplies | Q14: Paper | R14: Xerox 1967 | S14: 15.552 | T14: 3 | U14: 0.2 | V14: 5.4432
A15: 14 | B15: CA-2013-161389 | C15: =YEAR(Data!$D15) -> 2013 | D15: 41614 | E15: 41619 | F15: Standard Class | G15: IM-15070 | H15: Irene Maddox | I15: Consumer | J15: United States | K15: Seattle | L15: Washington | M15: 98103 | N15: West | O15: OFF-BI-10003656 | P15: Office Supplies | Q15: Binders | R15: Fellowes PB200 Plastic Comb Binding Machine | S15: 407.976 | T15: 3 | U15: 0.2 | V15: 132.5922 | W15: =Table_1[[#This Row],[Profit]]/Table_1[[#This Row],[Sales]] -> 0.325
A16: 15 | B16: US-2012-118983 | C16: =YEAR(Data!$D16) -> 2012 | D16: 41235 | E16: 41239 | F16: Standard Class | G16: HP-14815 | H16: Harold Pawlan | I16: Home Office | J16: United States | K16: Fort Worth | L16: Texas | M16: 76106 | N16: Central | O16: OFF-AP-10002311 | P16: Office Supplies | Q16: Appliances | R16: Holmes Replacement Filter for HEPA Air Cleaner, Very Large Room, HEPA Filter | S16: 68.81 | T16: 5 | U16: 0.8 | V16: -123.858
A17: 16 | B17: US-2012-118983 | C17: =YEAR(Data!$D17) -> 2012 | D17: 41235 | E17: 41239 | F17: Standard Class | G17: HP-14815 | H17: Harold Pawlan | I17: Home Office | J17: United States | K17: Fort Worth | L17: Texas | M17: 76106 | N17: Central | O17: OFF-BI-10000756 | P17: Office Supplies | Q17: Binders | R17: Storex DuraTech Recycled Plastic Frosted Binders | S17: 2.544 | T17: 3 | U17: 0.8 | V17: -3.816
A18: 17 | B18: CA-2011-105893 | C18: =YEAR(Data!$D18) -> 2011 | D18: 40858 | E18: 40865 | F18: Standard Class | G18: PK-19075 | H18: Pete Kriz | I18: Consumer | J18: United States | K18: Madison | L18: Wisconsin | M18: 53711 | N18: Central | O18: OFF-ST-10004186 | P18: Office Supplies | Q18: Storage | R18: Stur-D-Stor Shelving, Vertical 5-Shelf: 72"H x 36"W x 18 1/2"D | S18: 665.88 | T18: 6 | U18: 0 | V18: 13.3176
A19: 18 | B19: CA-2011-167164 | C19: =YEAR(Data!$D19) -> 2011 | D19: 40676 | E19: 40678 | F19: Second Class | G19: AG-10270 | H19: Alejandro Grove | I19: Consumer | J19: United States | K19: West Jordan | L19: Utah | M19: 84084 | N19: West | O19: OFF-ST-10000107 | P19: Office Supplies | Q19: Storage | R19: Fellowes Super Stor/Drawer | S19: 55.5 | T19: 2 | U19: 0 | V19: 9.99 | W19: =Table_1[[#This Row],[Profit]]/Table_1[[#This Row],[Sales]] -> 0.18
A20: 19 | B20: CA-2011-143336 | C20: =YEAR(Data!$D20) -> 2011 | D20: 40782 | E20: 40787 | F20: Second Class | G20: ZD-21925 | H20: Zuschuss Donatelli | I20: Consumer | J20: United States | K20: San Francisco | L20: California | M20: 94109 | N20: West | O20: OFF-AR-10003056 | P20: Office Supplies | Q20: Art | R20: Newell 341 | S20: 8.56 | T20: 2 | U20: 0 | V20: 2.4824 | W20: =Table_1[[#This Row],[Profit]]/Table_1[[#This Row],[Sales]] -> 0.29
A21: 20 | B21: CA-2011-143336 | C21: =YEAR(Data!$D21) -> 2011 | D21: 40782 | E21: 40787 | F21: Second Class | G21: ZD-21925 | H21: Zuschuss Donatelli | I21: Consumer | J21: United States | K21: San Francisco | L21: California | M21: 94109 | N21: West | O21: TEC-PH-10001949 | P21: Technology | Q21: Phones | R21: Cisco SPA 501G IP Phone | S21: 213.48 | T21: 3 | U21: 0.2 | V21: 16.011 | W21: =Table_1[[#This Row],[Profit]]/Table_1[[#This Row],[Sales]] -> 0.075
A22: 21 | B22: CA-2011-143336 | C22: =YEAR(Data!$D22) -> 2011 | D22: 40782 | E22: 40787 | F22: Second Class | G22: ZD-21925 | H22: Zuschuss Donatelli | I22: Consumer | J22: United States | K22: San Francisco | L22: California | M22: 94109 | N22: West | O22: OFF-BI-10002215 | P22: Office Supplies | Q22: Binders | R22: Wilson Jones Hanging View Binder, White, 1" | S22: 22.72 | T22: 4 | U22: 0.2 | V22: 7.384 | W22: =Table_1[[#This Row],[Profit]]/Table_1[[#This Row],[Sales]] -> 0.325
A23: 22 | B23: CA-2013-137330 | C23: =YEAR(Data!$D23) -> 2013 | D23: 41618 | E23: 41622 | F23: Standard Class | G23: KB-16585 | H23: Ken Black | I23: Corporate | J23: United States | K23: Fremont | L23: Nebraska | M23: 68025 | N23: Central | O23: OFF-AR-10000246 | P23: Office Supplies | Q23: Art | R23: Newell 318 | S23: 19.46 | T23: 7 | U23: 0 | V23: 5.0596
A24: 23 | B24: CA-2013-137330 | C24: =YEAR(Data!$D24) -> 2013 | D24: 41618 | E24: 41622 | F24: Standard Class | G24: KB-16585 | H24: Ken Black | I24: Corporate | J24: United States | K24: Fremont | L24: Nebraska | M24: 68025 | N24: Central | O24: OFF-AP-10001492 | P24: Office Supplies | Q24: Appliances | R24: Acco Six-Outlet Power Strip, 4' Cord Length | S24: 60.34 | T24: 7 | U24: 0 | V24: 15.6884
A25: 24 | B25: US-2014-156909 | C25: =YEAR(Data!$D25) -> 2014 | D25: 41837 | E25: 41839 | F25: Second Class | G25: SF-20065 | H25: Sandra Flanagan | I25: Consumer | J25: United States | K25: Philadelphia | L25: Pennsylvania | M25: 19140 | N25: East | O25: FUR-CH-10002774 | P25: Furniture | Q25: Chairs | R25: Global Deluxe Stacking Chair, Gray | S25: 71.372 | T25: 2 | U25: 0.3 | V25: -1.0196
A26: 25 | B26: CA-2012-106320 | C26: =YEAR(Data!$D26) -> 2012 | D26: 41177 | E26: 41182 | F26: Standard Class | G26: EB-13870 | H26: Emily Burns | I26: Consumer | J26: United States | K26: Orem | L26: Utah | M26: 84057 | N26: West | O26: FUR-TA-10000577 | P26: Furniture | Q26: Tables | R26: Bretford CR4500 Series Slim Rectangular Table | S26: 1044.63 | T26: 3 | U26: 0 | V26: 240.2649 | W26: =Table_1[[#This Row],[Profit]]/Table_1[[#This Row],[Sales]] -> 0.23
A27: 26 | B27: CA-2013-121755 | C27: =YEAR(Data!$D27) -> 2013 | D27: 41290 | E27: 41294 | F27: Second Class | G27: EH-13945 | H27: Eric Hoffmann | I27: Consumer | J27: United States | K27: Los Angeles | L27: California | M27: 90049 | N27: West | O27: OFF-BI-10001634 | P27: Office Supplies | Q27: Binders | R27: Wilson Jones Active Use Binders | S27: 11.648 | T27: 2 | U27: 0.2 | V27: 4.2224 | W27: =Table_1[[#This Row],[Profit]]/Table_1[[#This Row],[Sales]] -> 0.3625
A28: 27 | B28: CA-2013-121755 | C28: =YEAR(Data!$D28) -> 2013 | D28: 41290 | E28: 41294 | F28: Second Class | G28: EH-13945 | H28: Eric Hoffmann | I28: Consumer | J28: United States | K28: Los Angeles | L28: California | M28: 90049 | N28: West | O28: TEC-AC-10003027 | P28: Technology | Q28: Accessories | R28: Imation 8GB Mini TravelDrive USB 2.0 Flash Drive | S28: 90.57 | T28: 3 | U28: 0 | V28: 11.7741 | W28: =Table_1[[#This Row],[Profit]]/Table_1[[#This Row],[Sales]] -> 0.13
A29: 28 | B29: US-2012-150630 | C29: =YEAR(Data!$D29) -> 2012 | D29: 41169 | E29: 41173 | F29: Standard Class | G29: TB-21520 | H29: Tracy Blumstein | I29: Consumer | J29: United States | K29: Philadelphia | L29: Pennsylvania | M29: 19140 | N29: East | O29: FUR-BO-10004834 | P29: Furniture | Q29: Bookcases | R29: Riverside Palais Royal Lawyers Bookcase, Royale Cherry Finish | S29: 3083.43 | T29: 7 | U29: 0.5 | V29: -1665.0522
A30: 29 | B30: US-2012-150630 | C30: =YEAR(Data!$D30) -> 2012 | D30: 41169 | E30: 41173 | F30: Standard Class | G30: TB-21520 | H30: Tracy Blumstein | I30: Consumer | J30: United States | K30: Philadelphia | L30: Pennsylvania | M30: 19140 | N30: East | O30: OFF-BI-10000474 | P30: Office Supplies | Q30: Binders | R30: Avery Recycled Flexi-View Covers for Binding Systems | S30: 9.618 | T30: 2 | U30: 0.7 | V30: -7.0532
A31: 30 | B31: US-2012-150630 | C31: =YEAR(Data!$D31) -> 2012 | D31: 41169 | E31: 41173 | F31: Standard Class | G31: TB-21520 | H31: Tracy Blumstein | I31: Consumer | J31: United States | K31: Philadelphia | L31: Pennsylvania | M31: 19140 | N31: East | O31: FUR-FU-10004848 | P31: Furniture | Q31: Furnishings | R31: Howard Miller 13-3/4" Diameter Brushed Chrome Round Wall Clock | S31: 124.2 | T31: 3 | U31: 0.2 | V31: 15.525
A32: 31 | B32: US-2012-150630 | C32: =YEAR(Data!$D32) -> 2012 | D32: 41169 | E32: 41173 | F32: Standard Class | G32: TB-21520 | H32: Tracy Blumstein | I32: Consumer | J32: United States | K32: Philadelphia | L32: Pennsylvania | M32: 19140 | N32: East | O32: OFF-EN-10001509 | P32: Office Supplies | Q32: Envelopes | R32: Poly String Tie Envelopes | S32: 3.264 | T32: 2 | U32: 0.2 | V32: 1.1016
A33: 32 | B33: US-2012-150630 | C33: =YEAR(Data!$D33) -> 2012 | D33: 41169 | E33: 41173 | F33: Standard Class | G33: TB-21520 | H33: Tracy Blumstein | I33: Consumer | J33: United States | K33: Philadelphia | L33: Pennsylvania | M33: 19140 | N33: East | O33: OFF-AR-10004042 | P33: Office Supplies | Q33: Art | R33: BOSTON Model 1800 Electric Pencil Sharpeners, Putty/Woodgrain | S33: 86.304 | T33: 6 | U33: 0.2 | V33: 9.7092
A34: 33 | B34: US-2012-150630 | C34: =YEAR(Data!$D34) -> 2012 | D34: 41169 | E34: 41173 | F34: Standard Class | G34: TB-21520 | H34: Tracy Blumstein | I34: Consumer | J34: United States | K34: Philadelphia | L34: Pennsylvania | M34: 19140 | N34: East | O34: OFF-BI-10001525 | P34: Office Supplies | Q34: Binders | R34: Acco Pressboard Covers with Storage Hooks, 14 7/8" x 11", Executive Red | S34: 6.858 | T34: 6 | U34: 0.7 | V34: -5.715
A35: 34 | B35: US-2012-150630 | C35: =YEAR(Data!$D35) -> 2012 | D35: 41169 | E35: 41173 | F35: Standard Class | G35: TB-21520 | H35: Tracy Blumstein | I35: Consumer | J35: United States | K35: Philadelphia | L35: Pennsylvania | M35: 19140 | N35: East | O35: OFF-AR-10001683 | P35: Office Supplies | Q35: Art | R35: Lumber Crayons | S35: 15.76 | T35: 2 | U35: 0.2 | V35: 3.546
A36: 35 | B36: CA-2014-107727 | C36: =YEAR(Data!$D36) -> 2014 | D36: 41932 | E36: 41936 | F36: Second Class | G36: MA-17560 | H36: Matt Abelman | I36: Home Office | J36: United States | K36: Houston | L36: Texas | M36: 77095 | N36: Central | O36: OFF-PA-10000249 | P36: Office Supplies | Q36: Paper | R36: Staples | S36: 29.472 | T36: 3 | U36: 0.2 | V36: 9.9468
A37: 36 | B37: CA-2013-117590 | C37: =YEAR(Data!$D37) -> 2013 | D37: 41617 | E37: 41619 | F37: First Class | G37: GH-14485 | H37: Gene Hale | I37: Corporate | J37: United States | K37: Richardson | L37: Texas | M37: 75080 | N37: Central | O37: TEC-PH-10004977 | P37: Technology | Q37: Phones | R37: GE 30524EE4 | S37: 1097.544 | T37: 7 | U37: 0.2 | V37: 123.4737
A38: 37 | B38: CA-2013-117590 | C38: =YEAR(Data!$D38) -> 2013 | D38: 41617 | E38: 41619 | F38: First Class | G38: GH-14485 | H38: Gene Hale | I38: Corporate | J38: United States | K38: Richardson | L38: Texas | M38: 75080 | N38: Central | O38: FUR-FU-10003664 | P38: Furniture | Q38: Furnishings | R38: Electrix Architect's Clamp-On Swing Arm Lamp, Black | S38: 190.92 | T38: 5 | U38: 0.6 | V38: -147.963
A39: 38 | B39: CA-2012-117415 | C39: =YEAR(Data!$D39) -> 2012 | D39: 41270 | E39: 41274 | F39: Standard Class | G39: SN-20710 | H39: Steve Nguyen | I39: Home Office | J39: United States | K39: Houston | L39: Texas | M39: 77041 | N39: Central | O39: OFF-EN-10002986 | P39: Office Supplies | Q39: Envelopes | R39: #10-4 1/8" x 9 1/2" Premium Diagonal Seam Envelopes | S39: 113.328 | T39: 9 | U39: 0.2 | V39: 35.415
A40: 39 | B40: CA-2012-117415 | C40: =YEAR(Data!$D40) -> 2012 | D40: 41270 | E40: 41274 | F40: Standard Class | G40: SN-20710 | H40: Steve Nguyen | I40: Home Office | J40: United States | K40: Houston | L40: Texas | M40: 77041 | N40: Central | O40: FUR-BO-10002545 | P40: Furniture | Q40: Bookcases | R40: Atlantic Metals Mobile 3-Shelf Bookcases, Custom Colors | S40: 532.3992 | T40: 3 | U40: 0.32 | V40: -46.9764
...

Sheet KPI
A3: Row Labels | B3: Sum of Sales | D3: Row Labels | E3: Sum of Profit | G3: Row Labels | H3: Sum of Quantity | K3: Row Labels | L3: Count of Order ID | N3: Row Labels | O3: profit margin
A4: Jan | B4: 95365.938 | D4: Jan | E4: 9199.27 | G4: Jan | H4: 1500 | K4: Jan | L4: 387 | N4: Jan | O4: 0.096462849
A5: Feb | B5: 60172.649 | D5: Feb | E5: 10288.899 | G5: Feb | H5: 1068 | K5: Feb | L5: 301 | N5: Feb | O5: 0.17098962
A6: Mar | B6: 199252.98 | D6: Mar | E6: 26806.574 | G6: Mar | H6: 2491 | K6: Mar | L6: 680 | N6: Mar | O6: 0.13453537
A7: Apr | B7: 141851.57 | D7: Apr | E7: 13437.807 | G7: Apr | H7: 2441 | K7: Apr | L7: 663 | N7: Apr | O7: 0.094731465
A8: May | B8: 156122.29 | D8: May | E8: 22308.513 | G8: May | H8: 2850 | K8: May | L8: 750 | N8: May | O8: 0.14289128
A9: Jun | B9: 147082.61 | D9: Jun | E9: 20899.335 | G9: Jun | H9: 2644 | K9: Jun | L9: 709 | N9: Jun | O9: 0.14209249
A10: Jul | B10: 149580.84 | D10: Jul | E10: 13535.383 | G10: Jul | H10: 2705 | K10: Jul | L10: 708 | N10: Jul | O10: 0.09048875
A11: Aug | B11: 159589.45 | D11: Aug | E11: 21896.715 | G11: Aug | H11: 2796 | K11: Aug | L11: 710 | N11: Aug | O11: 0.13720653
A12: Sep | B12: 309770.1 | D12: Sep | E12: 37293.193 | G12: Sep | H12: 5073 | K12: Sep | L12: 1386 | N12: Sep | O12: 0.1203899
A13: Oct | B13: 197115.2 | D13: Oct | E13: 31469.664 | G13: Oct | H13: 3095 | K13: Oct | L13: 817 | N13: Oct | O13: 0.15965113
A14: Nov | B14: 349120.07 | D14: Nov | E14: 35825.537 | G14: Nov | H14: 5741 | K14: Nov | L14: 1462 | N14: Nov | O14: 0.10261666
A15: Dec | B15: 332177.16 | D15: Dec | E15: 43436.134 | G15: Dec | H15: 5469 | K15: Dec | L15: 1421 | N15: Dec | O15: 0.13076195
A16: Grand Total | B16: 2297200.9 | D16: Grand Total | E16: 286397.02 | G16: Grand Total | H16: 37873 | K16: Grand Total | L16: 9994 | N16: Grand Total | O16: 0.12467217
B17: =GETPIVOTDATA("[Measures].[Sum of Sales]",$A$3) -> 2297200.9 | E17: =GETPIVOTDATA("[Measures].[Sum of Profit]",$D$3) -> 286397.02 | H17: =GETPIVOTDATA("[Measures].[Sum of Quantity]",$G$3) -> 37873 | L17: =GETPIVOTDATA("[Measures].[Count of Order ID]",$K$3) -> 9994 | O17: =GETPIVOTDATA("[Measures].[profit margin]",$N$3) -> 0.12467217

Sheet analysis
A2: Row Labels | B2: Sum of Sales | D2: Row Labels | E2: Count of Order ID | G2: Row Labels | H2: Sum of Profit | K2: Row Labels | L2: Sum of Sales | M2: Sum of Profit | Z2: Row Labels | AA2: Sum of Profit | AC2: CATEGORY | AD2: PROFIT | AG2: Row Labels | AH2: Sum of Sales | AL2: Row Labels | AM2: Sum of Sales
A3: Central | B3: 501239.89 | D3: 2011 | E3: 1993 | G3: Furniture | H3: 18451.273 | K3: Jan | L3: 95365.938 | M3: 9199.27 | Z3: Furniture | AA3: 18451.273 | AC3: =Z3 -> Furniture | AD3: =GETPIVOTDATA("[Measures].[Sum of Profit]",$Z$2,"[Table_1].[Category]","[Table_1].[Category].&[Furniture]") -> 18451.273 | AG3: Furniture | AH3: 0.32300171 | AL3: Alabama | AM3: 19510.64 | AO3: STATE | AP3: SALES | AV3: Row Labels | AW3: Sum of Sales
A4: East | B4: 678781.24 | D4: 2012 | E4: 2102 | G4: Office Supplies | H4: 122490.8 | K4: Feb | L4: 60172.649 | M4: 10288.899 | Z4: Office Supplies | AA4: 122490.8 | AC4: =Z4 -> Office Supplies | AD4: =GETPIVOTDATA("[Measures].[Sum of Profit]",$Z$2,"[Table_1].[Category]","[Table_1].[Category].&[Office Supplies]") -> 122490.8 | AG4: Office Supplies | AH4: 0.31301008 | AL4: Arizona | AM4: 35282.001 | AO4: =AL3 -> Alabama | AP4: 19510.64 | AV4: Binders | AW4: 203412.73
A5: South | B5: 391721.91 | D5: 2013 | E5: 2580 | G5: Technology | H5: 145454.95 | K5: Mar | L5: 199252.98 | M5: 26806.574 | Z5: Technology | AA5: 145454.95 | AC5: =Z5 -> Technology | AD5: =GETPIVOTDATA("[Measures].[Sum of Profit]",$Z$2,"[Table_1].[Category]","[Table_1].[Category].&[Technology]") -> 145454.95 | AG5: Technology | AH5: 0.36398821 | AL5: Arkansas | AM5: 11678.13 | AO5: =AL4 -> Arizona | AP5: 35282.001 | AV5: Tables | AW5: 206965.53
A6: West | B6: 725457.82 | D6: 2014 | E6: 3319 | K6: Apr | L6: 141851.57 | M6: 13437.807 | AC6: GRAND TOTAL | AD6: =SUM(AD3:AD5) -> 286397.02 | AL6: California | AM6: 457687.63 | AO6: =AL5 -> Arkansas | AP6: 11678.13 | AV6: Storage | AW6: 223843.61
K7: May | L7: 156122.29 | M7: 22308.513 | AL7: Colorado | AM7: 32108.118 | AO7: =AL6 -> California | AP7: 457687.63 | AV7: Chairs | AW7: 328449.1
K8: Jun | L8: 147082.61 | M8: 20899.335 | AL8: Connecticut | AM8: 13384.357 | AO8: =AL7 -> Colorado | AP8: 32108.118 | AV8: Phones | AW8: 330007.05 | AZ8: Sum of Profit
K9: Jul | L9: 149580.84 | M9: 13535.383 | AL9: Delaware | AM9: 27451.069 | AO9: =AL8 -> Connecticut | AP9: 13384.357 | AZ9: 286397.02
K10: Aug | L10: 159589.45 | M10: 21896.715 | AL10: District of Columbia | AM10: 2865.02 | AO10: =AL9 -> Delaware | AP10: 27451.069
K11: Sep | L11: 309770.1 | M11: 37293.193 | AL11: Florida | AM11: 89473.708 | AO11: =AL10 -> District of Columbia | AP11: 2865.02
K12: Oct | L12: 197115.2 | M12: 31469.664 | AL12: Georgia | AM12: 49095.84 | AO12: =AL11 -> Florida | AP12: 89473.708
K13: Nov | L13: 349120.07 | M13: 35825.537 | AL13: Idaho | AM13: 4382.486 | AO13: =AL12 -> Georgia | AP13: 49095.84
K14: Dec | L14: 332177.16 | M14: 43436.134 | AL14: Illinois | AM14: 80166.101 | AO14: =AL13 -> Idaho | AP14: 4382.486
AL15: Indiana | AM15: 53555.36 | AO15: =AL14 -> Illinois | AP15: 80166.101
AL16: Iowa | AM16: 4579.76 | AO16: =AL15 -> Indiana | AP16: 53555.36
AL17: Kansas | AM17: 2914.31 | AO17: =AL16 -> Iowa | AP17: 4579.76
AL18: Kentucky | AM18: 36591.75 | AO18: =AL17 -> Kansas | AP18: 2914.31
AL19: Louisiana | AM19: 9217.03 | AO19: =AL18 -> Kentucky | AP19: 36591.75
AL20: Maine | AM20: 1270.53 | AO20: =AL19 -> Louisiana | AP20: 9217.03
AL21: Maryland | AM21: 23705.523 | AO21: =AL20 -> Maine | AP21: 1270.53
AL22: Massachusetts | AM22: 28634.434 | AO22: =AL21 -> Maryland | AP22: 23705.523
AL23: Michigan | AM23: 76269.614 | AO23: =AL22 -> Massachusetts | AP23: 28634.434
AL24: Minnesota | AM24: 29863.15 | AO24: =AL23 -> Michigan | AP24: 76269.614
AL25: Mississippi | AM25: 10771.34 | AO25: =AL24 -> Minnesota | AP25: 29863.15
AL26: Missouri | AM26: 22205.15 | AO26: =AL25 -> Mississippi | AP26: 10771.34
... AL51: Wyoming | AM51: 1603.136 | AO51: =AL50 -> Wisconsin | AP51: 32114.61
AO52: =AL51 -> Wyoming | AP52: 1603.136

Sheet Dashboard
